<?xml version="1.0" encoding="utf-8"?>
<!-- This URDF was automatically created by SolidWorks to URDF Exporter! Originally created by
Stephen Brawner (brawner@gmail.com) 
     Commit Version: 1.6.0-4-g7f85cfe  Build Version: 1.6.7995.38578
     For more information, please see http://wiki.ros.org/sw_urdf_exporter -->
<robot
  name="carurdf">
  <link
    name="base_link">
    <inertial>
      <origin
        xyz="0.0295434579640815 -5.37183247883988E-09 0.0969137532977708"
        rpy="0 0 0" />
      <mass
        value="246.126252736902" />
      <inertia
        ixx="3.41645415948318"
        ixy="-2.2747223692862E-06"
        ixz="-0.148729463416917"
        iyy="15.1999564174256"
        iyz="2.34347740787178E-07"
        izz="16.6674947818123" />
    </inertial>
    <visual>
      <origin
        xyz="0 0 0"
        rpy="0 0 0" />
      <geometry>
        <mesh
          filename="package://carurdf/meshes/carbody.dae" />
      </geometry>
      <material
        name="">
        <color
          rgba="0.686274509803922 0.658823529411765 0.63921568627451 1" />
      </material>
    </visual>
    <collision>
      <origin
        xyz="0 0 0"
        rpy="0 0 0" />
      <geometry>
        <mesh
          filename="package://carurdf/meshes/carbody.dae" />
      </geometry>
    </collision>
  </link>
  <link
    name="wheel11">
    <inertial>
      <origin
        xyz="-4.2392E-09 -0.020059 -1.4979E-10"
        rpy="0 0 0" />
      <mass
        value="1.2166" />
      <inertia
        ixx="0.0020082"
        ixy="3.055E-11"
        ixz="-7.3408E-10"
        iyy="0.0036467"
        iyz="-7.7296E-11"
        izz="0.0020082" />
    </inertial>
    <visual>
      <origin
        xyz="0 0 0"
        rpy="0 0 0" />
      <geometry>
        <mesh
          filename="package://carurdf/meshes/wheel11.STL" />
      </geometry>
      <material
        name="">
        <color
          rgba="0.29804 0.29804 0.29804 1" />
      </material>
    </visual>
    <collision>
      <origin
        xyz="0 0 0"
        rpy="0 0 0" />
      <geometry>
        <mesh
          filename="package://carurdf/meshes/wheel11.STL" />
      </geometry>
    </collision>
  </link>
  <joint
    name="base2w11"
    type="continuous">
    <origin
      xyz="0.33457626735416 0.216385938981358 0.0248226035845359"
      rpy="0 0 0" />
    <parent
      link="base_link" />
    <child
      link="wheel11" />
    <axis
      xyz="0 1 0" />
  </joint>
  <link
    name="wheel12">
    <inertial>
      <origin
        xyz="-3.995E-09 0.020059 1.4262E-09"
        rpy="0 0 0" />
      <mass
        value="1.2166" />
      <inertia
        ixx="0.0020082"
        ixy="-5.2517E-11"
        ixz="9.7967E-10"
        iyy="0.0036467"
        iyz="-6.442E-11"
        izz="0.0020082" />
    </inertial>
    <visual>
      <origin
        xyz="0 0 0"
        rpy="0 0 0" />
      <geometry>
        <mesh
          filename="package://carurdf/meshes/wheel12.STL" />
      </geometry>
      <material
        name="">
        <color
          rgba="0.29804 0.29804 0.29804 1" />
      </material>
    </visual>
    <collision>
      <origin
        xyz="0 0 0"
        rpy="0 0 0" />
      <geometry>
        <mesh
          filename="package://carurdf/meshes/wheel12.STL" />
      </geometry>
    </collision>
  </link>
  <joint
    name="base2w12"
    type="continuous">
    <origin
      xyz="0.334576267354161 -0.216385938981358 0.0248226035845345"
      rpy="0 0 0" />
    <parent
      link="base_link" />
    <child
      link="wheel12" />
    <axis
      xyz="0 1 0" />
  </joint>
  <link
    name="wheel21">
    <inertial>
      <origin
        xyz="-4.2077E-09 -0.020059 -5.3784E-10"
        rpy="0 0 0" />
      <mass
        value="1.2166" />
      <inertia
        ixx="0.0020082"
        ixy="3.7508E-11"
        ixz="-8.4202E-10"
        iyy="0.0036467"
        iyz="-7.417E-11"
        izz="0.0020082" />
    </inertial>
    <visual>
      <origin
        xyz="0 0 0"
        rpy="0 0 0" />
      <geometry>
        <mesh
          filename="package://carurdf/meshes/wheel21.STL" />
      </geometry>
      <material
        name="">
        <color
          rgba="0.29804 0.29804 0.29804 1" />
      </material>
    </visual>
    <collision>
      <origin
        xyz="0 0 0"
        rpy="0 0 0" />
      <geometry>
        <mesh
          filename="package://carurdf/meshes/wheel21.STL" />
      </geometry>
    </collision>
  </link>
  <joint
    name="base2w21"
    type="continuous">
    <origin
      xyz="-0.319805472903942 0.194956347276155 0.0248226035845313"
      rpy="0 0 0" />
    <parent
      link="base_link" />
    <child
      link="wheel21" />
    <axis
      xyz="0 1 0" />
  </joint>
  <link
    name="wheel22">
    <inertial>
      <origin
        xyz="1.3725E-10 0.020059 2.5463E-10"
        rpy="0 0 0" />
      <mass
        value="1.2166" />
      <inertia
        ixx="0.0020082"
        ixy="1.989E-11"
        ixz="3.0059E-10"
        iyy="0.0036467"
        iyz="-5.2489E-11"
        izz="0.0020082" />
    </inertial>
    <visual>
      <origin
        xyz="0 0 0"
        rpy="0 0 0" />
      <geometry>
        <mesh
          filename="package://carurdf/meshes/wheel22.STL" />
      </geometry>
      <material
        name="">
        <color
          rgba="0.29804 0.29804 0.29804 1" />
      </material>
    </visual>
    <collision>
      <origin
        xyz="0 0 0"
        rpy="0 0 0" />
      <geometry>
        <mesh
          filename="package://carurdf/meshes/wheel22.STL" />
      </geometry>
    </collision>
  </link>
  <joint
    name="base2w22"
    type="continuous">
    <origin
      xyz="-0.319805472903942 -0.194956347276155 0.02482260358453"
      rpy="0 0 0" />
    <parent
      link="base_link" />
    <child
      link="wheel22" />
    <axis
      xyz="0 1 0" />
  </joint>
</robot>